<?xml version="1.0" ?>
<robot name="robotaksi" xmlns:xacro="http://www.ros.org/wiki/xacro">

<xacro:arg name="is_sim" default="true"/>
<xacro:arg name="is_ignition" default="true"/>

<xacro:include filename="$(find robotaksi_description)/urdf/materials.xacro" />
<xacro:include filename="$(find robotaksi_description)/urdf/robotaksi.gazebo" />
<xacro:include filename="$(find robotaksi_description)/urdf/rplidar_s2.xacro"/>
<xacro:include filename="$(find robotaksi_description)/urdf/d435_camera.xacro"/>
<xacro:include filename="$(find robotaksi_description)/urdf/imu.xacro"/>

<xacro:property name="wheel_radius" value="0.3"/>
<xacro:property name="wheel_width" value="0.2"/>
<xacro:property name="wheel_mass" value="90"/>

<xacro:property name="knuckle_mass" value="5"/>
<xacro:property name="knuckle_radius" value="0.05"/>
<xacro:property name="knuckle_height" value="0.1"/>

<link name="base_footprint"/>

<joint name="base_footprint_joint" type="fixed">
    <parent link="base_footprint"/>
    <child link="base_link"/>
    <origin xyz="0 0 0" rpy="0 0 0"/>
</joint>

<link name="base_link">
  <inertial>
    <origin xyz="0.015227403646740032 -0.10161088779130478 0.2098030237602473" rpy="0 0 0"/>
    <mass value="80"/>
    <inertia ixx="56.423509" iyy="169.853499" izz="202.959351" ixy="-0.254428" iyz="0.016951" ixz="0.803829"/>
  </inertial>
  <visual>
    <origin xyz="0 0 0" rpy="0 0 0"/>
    <geometry>
      <mesh filename="file://$(find robotaksi_description)/meshes/base_link.stl" scale="0.001 0.001 0.001"/>
    </geometry>
    <material name="silver"/>
  </visual>
  <collision>
    <origin xyz="0 0 0" rpy="0 0 0"/>
    <geometry>
      <mesh filename="file://$(find robotaksi_description)/meshes/base_link.stl" scale="0.001 0.001 0.001"/>
    </geometry>
  </collision>
</link>

<link name="right_front_knuckle">
    <visual>
        <geometry>
            <cylinder radius="${knuckle_radius}" length="${knuckle_height}"/>
        </geometry>
        <material name="grey"/>
    </visual>
    <collision>
        <geometry>
            <cylinder radius="${knuckle_radius}" length="${knuckle_height}"/>
        </geometry>
    </collision>
    <inertial>
        <mass value="${knuckle_mass}"/>
        <inertia ixx="0.001" ixy="0.0" ixz="0.0" iyy="0.001" iyz="0.0" izz="0.001"/>
    </inertial>
</link>

<link name="left_front_knuckle">
    <visual>
        <geometry>
            <cylinder radius="${knuckle_radius}" length="${knuckle_height}"/>
        </geometry>
        <material name="grey"/>
    </visual>
    <collision>
        <geometry>
            <cylinder radius="${knuckle_radius}" length="${knuckle_height}"/>
        </geometry>
    </collision>
    <inertial>
        <mass value="${knuckle_mass}"/>
        <inertia ixx="0.001" ixy="0.0" ixz="0.0" iyy="0.001" iyz="0.0" izz="0.001"/>
    </inertial>
</link>

<link name="right_front_wheel_1">
  <inertial>
    <origin xyz="3.046767539371942e-07 0.03679554827999909 6.43434692193523e-08" rpy="0 0 0"/>
    <mass value="90.46665125380633"/>
    <inertia ixx="2.592541" iyy="5.069951" izz="2.592542" ixy="-0.0" iyz="-0.0" ixz="0.0"/>
  </inertial>
  <visual>
    <origin xyz="-0.725318 0.705779 -0.279785" rpy="0 0 0"/>
    <geometry>
      <mesh filename="file://$(find robotaksi_description)/meshes/right_front_wheel_1.stl" scale="0.001 0.001 0.001"/>
    </geometry>
    <material name="silver"/>
  </visual>
  <collision>
    <origin xyz="-0.725318 0.705779 -0.279785" rpy="0 0 0"/>
    <geometry>
      <mesh filename="file://$(find robotaksi_description)/meshes/right_front_wheel_1.stl" scale="0.001 0.001 0.001"/>
    </geometry>
  </collision>
</link>

<link name="right_back_wheel_1">
  <inertial>
    <origin xyz="3.046767904635317e-07 0.018195548280076745 6.434341576211366e-08" rpy="0 0 0"/>
    <mass value="90.46665125382138"/>
    <inertia ixx="2.592541" iyy="5.069951" izz="2.592542" ixy="-0.0" iyz="-0.0" ixz="0.0"/>
  </inertial>
  <visual>
    <origin xyz="0.674682 0.705779 -0.279785" rpy="0 0 0"/>
    <geometry>
      <mesh filename="file://$(find robotaksi_description)/meshes/right_back_wheel_1.stl" scale="0.001 0.001 0.001"/>
    </geometry>
    <material name="silver"/>
  </visual>
  <collision>
    <origin xyz="0.674682 0.705779 -0.279785" rpy="0 0 0"/>
    <geometry>
      <mesh filename="file://$(find robotaksi_description)/meshes/right_back_wheel_1.stl" scale="0.001 0.001 0.001"/>
    </geometry>
  </collision>
</link>

<link name="left_back_wheel_1">
  <inertial>
    <origin xyz="3.105141199721828e-07 -0.03679539112418956 3.0458926220111593e-07" rpy="0 0 0"/>
    <mass value="90.46665125379855"/>
    <inertia ixx="2.592541" iyy="5.069951" izz="2.592542" ixy="-0.0" iyz="0.0" ixz="-0.0"/>
  </inertial>
  <visual>
    <origin xyz="0.674682 -0.50652 -0.279262" rpy="0 0 0"/>
    <geometry>
      <mesh filename="file://$(find robotaksi_description)/meshes/left_back_wheel_1.stl" scale="0.001 0.001 0.001"/>
    </geometry>
    <material name="silver"/>
  </visual>
  <collision>
    <origin xyz="0.674682 -0.50652 -0.279262" rpy="0 0 0"/>
    <geometry>
      <mesh filename="file://$(find robotaksi_description)/meshes/left_back_wheel_1.stl" scale="0.001 0.001 0.001"/>
    </geometry>
  </collision>
</link>

<link name="left_front_wheel_1">
  <inertial>
    <origin xyz="3.1063828642707847e-07 -0.036795391124162136 3.062833157096989e-07" rpy="0 0 0"/>
    <mass value="90.46665125379138"/>
    <inertia ixx="2.592541" iyy="5.069951" izz="2.592542" ixy="-0.0" iyz="-0.0" ixz="-1e-06"/>
  </inertial>
  <visual>
    <origin xyz="-0.725318 -0.50652 -0.279262" rpy="0 0 0"/>
    <geometry>
      <mesh filename="file://$(find robotaksi_description)/meshes/left_front_wheel_1.stl" scale="0.001 0.001 0.001"/>
    </geometry>
    <material name="silver"/>
  </visual>
  <collision>
    <origin xyz="-0.725318 -0.50652 -0.279262" rpy="0 0 0"/>
    <geometry>
      <mesh filename="file://$(find robotaksi_description)/meshes/left_front_wheel_1.stl" scale="0.001 0.001 0.001"/>
    </geometry>
  </collision>
</link>

<joint name="right_front_steering_joint" type="revolute">
    <parent link="base_link"/>
    <child link="right_front_knuckle"/>
    <origin xyz="0.725318 -0.705779 0.279785" rpy="0 0 0"/>
    <axis xyz="0 0 1"/>
    <limit lower="-0.516" upper="0.516" effort="100" velocity="1"/>
</joint>

<joint name="left_front_steering_joint" type="revolute">
    <parent link="base_link"/>
    <child link="left_front_knuckle"/>
    <origin xyz="0.725318 0.50652 0.279262" rpy="0 0 0"/>
    <axis xyz="0 0 1"/>
    <limit lower="-0.516" upper="0.516" effort="100" velocity="1"/>
</joint>

<joint name="right_front" type="continuous">
  <origin xyz="0 0 0" rpy="0 0 0"/>
  <parent link="right_front_knuckle"/>
  <child link="right_front_wheel_1"/>
  <axis xyz="0.0 1.0 0.0"/>
</joint>

<joint name="right_back" type="continuous">
  <origin xyz="-0.674682 -0.705779 0.279785" rpy="0 0 0"/>
  <parent link="base_link"/>
  <child link="right_back_wheel_1"/>
  <axis xyz="0.0 1.0 0.0"/>
</joint>

<joint name="left_back" type="continuous">
  <origin xyz="-0.674682 0.50652 0.279262" rpy="0 0 0"/>
  <parent link="base_link"/>
  <child link="left_back_wheel_1"/>
  <axis xyz="0.0 1.0 0.0"/>
</joint>

<joint name="left_front" type="continuous">
  <origin xyz="0 0 0" rpy="0 0 0"/>
  <parent link="left_front_knuckle"/>
  <child link="left_front_wheel_1"/>
  <axis xyz="0.0 1.0 0.0"/>
</joint>

<ros2_control name="RobotSystem" type="system">
    <!-- ros2_control Gazebo -->
    <xacro:if value="$(arg is_sim)">
        <!-- ROS 2 Humble -->
        <xacro:if value="$(arg is_ignition)">
            <hardware><plugin>gz_ros2_control/GazeboSimSystem</plugin></hardware>
        </xacro:if>

        <!-- ROS 2 Iron or above -->
        <xacro:unless value="$(arg is_ignition)">
            <hardware><plugin>gz_ros2_control/GazeboSimSystem</plugin></hardware>
        </xacro:unless>
    </xacro:if>

    <!-- ros2_control Real Robot (Placeholder) -->
    <xacro:unless value="$(arg is_sim)">
        <hardware><plugin>robotaksi_firmware/RobotaksiHardwareInterface</plugin></hardware>
    </xacro:unless>

    <joint name="left_front_steering_joint">
        <command_interface name="position"/>
        <state_interface name="position"/>
        <state_interface name="velocity"/>
    </joint>
    <joint name="right_front_steering_joint">
        <command_interface name="position"/>
        <state_interface name="position"/>
        <state_interface name="velocity"/>
    </joint>
    <joint name="left_front">
        <state_interface name="position"/>
        <state_interface name="velocity"/>
        <param name="wheel_radius">${wheel_radius}</param>
    </joint>
    <joint name="right_front">
        <state_interface name="position"/>
        <state_interface name="velocity"/>
        <param name="wheel_radius">${wheel_radius}</param>
    </joint>
    <joint name="left_back">
        <command_interface name="velocity"/>
        <state_interface name="position"/>
        <state_interface name="velocity"/>
        <param name="wheel_radius">${wheel_radius}</param>
    </joint>
    <joint name="right_back">
        <command_interface name="velocity"/>
        <state_interface name="position"/>
        <state_interface name="velocity"/>
        <param name="wheel_radius">${wheel_radius}</param>
    </joint>
</ros2_control>

<transmission name="left_front_steering_trans">
    <type>transmission_interface/SimpleTransmission</type>
    <joint name="left_front_steering_joint">
        <hardwareInterface>hardware_interface/PositionJointInterface</hardwareInterface>
    </joint>
    <actuator name="left_front_steering_actuator">
        <hardwareInterface>hardware_interface/PositionJointInterface</hardwareInterface>
        <mechanicalReduction>1</mechanicalReduction>
    </actuator>
</transmission>

<transmission name="right_front_steering_trans">
    <type>transmission_interface/SimpleTransmission</type>
    <joint name="right_front_steering_joint">
        <hardwareInterface>hardware_interface/PositionJointInterface</hardwareInterface>
    </joint>
    <actuator name="right_front_steering_actuator">
        <hardwareInterface>hardware_interface/PositionJointInterface</hardwareInterface>
        <mechanicalReduction>1</mechanicalReduction>
    </actuator>
</transmission>

<transmission name="left_back_transmission">
    <type>transmission_interface/SimpleTransmission</type>
    <joint name="left_back">
        <hardwareInterface>hardware_interface/VelocityJointInterface</hardwareInterface>
    </joint>
    <actuator name="left_back_motor">
        <hardwareInterface>hardware_interface/VelocityJointInterface</hardwareInterface>
        <mechanicalReduction>1</mechanicalReduction>
    </actuator>
</transmission>

<transmission name="right_back_transmission">
    <type>transmission_interface/SimpleTransmission</type>
    <joint name="right_back">
        <hardwareInterface>hardware_interface/VelocityJointInterface</hardwareInterface>
    </joint>
    <actuator name="right_back_motor">
        <hardwareInterface>hardware_interface/VelocityJointInterface</hardwareInterface>
        <mechanicalReduction>1</mechanicalReduction>
    </actuator>
</transmission>

<xacro:rplidar_s2 parent="base_link" name="lidar" xyz="1.07 -0.015 0.63" rpy="0 0 0"/>
<xacro:rplidar_s2_gazebo_plugin name="lidar"/>

<xacro:realsense_d435 parent="base_link" name="camera" xyz="0.46 -0.10 0.985" rpy="0 0 0"/>
<xacro:d435_gazebo_plugins name="camera"/>

<xacro:imu_sensor parent="base_link" name="imu" xyz="0 0 0.1" rpy="0 0 0"/>

</robot> 